<?xml version='1.0'?>
<robot name="my_robot" xmlns:xacro="http://www.ros.org/wiki/xacro">
  <xacro:include filename="$(find my_robot)/urdf/my_robot.gazebo" />
  <link name="robot_footprint">
  </link>
  
  <joint name="robot_footprint_joint" type="fixed">
    <origin xyz="0 0 0" rpy="0 0 0"/>
	<parent link="robot_footprint"/>
	<child link="chassis"/>
  </joint>
  
  <link name="chassis">
	<inertial>
	  <mass value="10"/>
          <origin xyz="0.0 0 0.0" rpy=" 0 0 0"/>
           <inertia
             ixx="0.1" ixy="0" ixz="0"
             iyy="0.1" iyz="0"
             izz="0.1"
          />
        </inertial>
	<visual>
	  <origin xyz="0 0 0.05" rpy="0 0 0"/>
	  <geometry>
	    <box size="0.3 0.2 0.05"/>
	  </geometry>
	</visual>
	<collision>
	  <origin xyz="0 0 0.05" rpy="0 0 0"/>
	  <geometry>
	    <box size="0.3 0.2 0.05"/>
	  </geometry>
	</collision>
	<visual>
	  <origin xyz="0.10 0 0.025" rpy="0 0 0"/>
	  <geometry>
	    <sphere radius ="0.025"/>
	  </geometry>
	</visual>
	<collision>
	  <origin xyz="0.10 0 0.025" rpy="0 0 0"/>
	  <geometry>
	    <sphere radius ="0.025"/>
	  </geometry>
	</collision>
	<visual>
	  <origin xyz="-0.10 0 0.025" rpy="0 0 0"/>
	  <geometry>
	    <sphere radius ="0.025"/>
	  </geometry>
	</visual>
	<collision>
	  <origin xyz="-0.10 0 0.025" rpy="0 0 0"/>
	  <geometry>
	    <sphere radius ="0.025"/>
	  </geometry>
	</collision>
  </link>	


  <link name="left_wheel">
	<inertial>
	  <mass value="5"/>
          <origin xyz="0.0 0 0" rpy=" 0 0 0"/>
          <inertia
             ixx="0.1" ixy="0" ixz="0"
             iyy="0.1" iyz="0"
             izz="0.1"
          />
        </inertial>
	<visual>
	  <origin xyz="0 0 0" rpy="0 1.5707 1.5707"/>
	  <geometry>
	    <cylinder length="0.05" radius="0.05"/>
	  </geometry>
	</visual>
	<collision>
	  <origin xyz="0 0 0" rpy="0 1.5707 1.5707"/>
	  <geometry>
	    <cylinder length="0.05" radius="0.05"/>
	  </geometry>
	</collision>
  </link>

  <link name="right_wheel">
	<inertial>
	  <mass value="5"/>
          <origin xyz="0.0 0 0" rpy=" 0 0 0"/>
          <inertia
             ixx="0.1" ixy="0" ixz="0"
             iyy="0.1" iyz="0"
             izz="0.1"
          />
        </inertial>
	<visual>
	  <origin xyz="0 0 0" rpy="0 1.5707 1.5707"/>
	  <geometry>
	    <cylinder length="0.05" radius="0.05"/>
	  </geometry>
	</visual>
	<collision>
	  <origin xyz="0 0 0" rpy="0 1.5707 1.5707"/>
	  <geometry>
	    <cylinder length="0.05" radius="0.05"/>
	  </geometry>
	</collision>
  </link>

  <link name="camera">
	<inertial>
	  <mass value="0.0"/>
          <origin xyz="0.0 0 0.0" rpy=" 0 0 0"/>
           <inertia
             ixx="0.1e-6" ixy="0" ixz="0"
             iyy="0.1e-6" iyz="0"
             izz="0.1e-6"
          />
        </inertial>
	<visual>
	  <origin xyz="0 0 0" rpy="0 0 0"/>
	  <geometry>
	    <box size="0.05 0.05 0.05"/>
	  </geometry>
	</visual>
	<collision>
	  <origin xyz="0 0 0" rpy="0 0 0"/>
	  <geometry>
	    <box size="0.05 0.05 0.05"/>
	  </geometry>
	</collision>
  </link>

  <link name="hokuyo">
	<inertial>
	  <mass value="1e-5"/>
          <origin xyz="0.0 0 0.0" rpy=" 0 0 0"/>
           <inertia
             ixx="0.1e-6" ixy="0" ixz="0"
             iyy="0.1e-6" iyz="0"
             izz="0.1e-6"
          />
        </inertial>
	<visual>
	  <origin xyz="0 0 0" rpy="0 0 0"/>
	  <geometry>
            <mesh filename="package://my_robot/meshes/hokuyo.dae"/>
	  </geometry>
	</visual>
	<collision>
	  <origin xyz="0 0 0" rpy="0 0 0"/>
	  <geometry>
	    <box size="0.1 0.1 0.1"/>
	  </geometry>
	</collision>
  </link>

  <link name="camera_link_optical">
  </link>

  <joint type="continuous" name="left_wheel_hinge">
    <origin xyz = "0 0.125 0.05" rpy="0 0 0"/>
    <child link = "left_wheel"/>
    <parent link = "chassis"/>
    <axis xyz="0 1 0" rpy="0 0 0"/>
    <limit effort="10000" velocity="1000"/>
    <dynamics damping="0.1" friction="0.5"/>
  </joint>

  <joint type="continuous" name="right_wheel_hinge">
    <origin xyz = "0 -0.125 0.05" rpy="0 0 0"/>
    <child link = "right_wheel"/>
    <parent link = "chassis"/>
    <axis xyz="0 1 0" rpy="0 0 0"/>
    <limit effort="10000" velocity="1000"/>
    <dynamics damping="0.1" friction="0.5"/>
  </joint>

  <joint type="fixed" name="camera_joint">
    <origin xyz = "0.15 0 0.05" rpy="0 0 0"/>
    <child link = "camera"/>
    <parent link = "chassis"/>
    <axis xyz="1 0 0" rpy="0 0 0"/>
  </joint>

  <joint type="fixed" name="hokuyo_joint">
    <origin xyz = "0 0 0.15" rpy="0 0 0"/>
    <child link = "hokuyo"/>
    <parent link = "chassis"/>
    <axis xyz="0 0 1" rpy="0 0 0"/>
  </joint>

  <joint name="camera_optical_joint" type="fixed">
    <origin xyz="0 0 0" rpy="-1.5707 0 -1.5707"/>
    <parent link="camera"/>
    <child link="camera_link_optical"/>
  </joint>

  <gazebo reference="chassis">
   <material>Gazebo/Blue</material>
  </gazebo>

  <gazebo reference="camera">
   <material>Gazebo/Black</material>
  </gazebo>

</robot>
